Workbook

Sheet Clients_Churn
A1: Nb_Client | B1: ID_Client | C1: Province_Client | D1: Anciennete_Mois | E1: Type_Forfait | F1: Duree_Cumulee_Panne_Min | G1: Facture_Mensuelle | H1: Plaintes_Service_Client | I1: Remise (%) | J1: Perte_Financiere | K1: Client_Impacte | L1: Type_client
A2: 1 | B2: CLI-00007 | C2: Tanganyika | D2: 110 | E2: Bloqué 5Go | F2: 112 | G2: 98.95 | H2: 5 | I2: =IF(AND(CLIENTS_CHURN[[#This Row],[Duree_Cumulee_Panne_Min]]>720,CLIENTS_CHURN[[#This Row],[Anciennete_Mois]]>60),"70%",IF(OR(AND(CLIENTS_CHURN[[#This Row],[Duree_Cumulee_Panne_Min]]>=240,CLIENTS_CHURN[[#This Row],[Duree_Cumulee_Panne_Min]]<=720),AND(CLIENTS_CHURN[[#This Row],[Anciennete_Mois]]<60,CLIENTS_CHURN[[#This Row],[Type_Forfait]]="Premium")),"45%",IF(CLIENTS_CHURN[[#This Row],[Type_Forfait]]="Pro Monde","10%","0"))) -> 0 | J2: =CLIENTS_CHURN[[#This Row],[Facture_Mensuelle]]*CLIENTS_CHURN[[#This Row],[Remise (%)]] -> 0 | K2: =IF(CLIENTS_CHURN[[#This Row],[Duree_Cumulee_Panne_Min]]>0,1,0) -> 1 | L2: =IF(CLIENTS_CHURN[[#This Row],[Type_Forfait]]="Pro Monde","B2B","B2C") -> B2C
A3: =A2+1 -> 2 | B3: CLI-00009 | C3: Kwilu | D3: 105 | E3: Pro Monde | F3: 297 | G3: 84.66 | H3: 2 | I3: =IF(AND(CLIENTS_CHURN[[#This Row],[Duree_Cumulee_Panne_Min]]>720,CLIENTS_CHURN[[#This Row],[Anciennete_Mois]]>60),"70%",IF(OR(AND(CLIENTS_CHURN[[#This Row],[Duree_Cumulee_Panne_Min]]>=240,CLIENTS_CHURN[[#This Row],[Duree_Cumulee_Panne_Min]]<=720),AND(CLIENTS_CHURN[[#This Row],[Anciennete_Mois]]<60,CLIENTS_CHURN[[#This Row],[Type_Forfait]]="Premium")),"45%",IF(CLIENTS_CHURN[[#This Row],[Type_Forfait]]="Pro Monde","10%","0"))) -> 45% | J3: =CLIENTS_CHURN[[#This Row],[Facture_Mensuelle]]*CLIENTS_CHURN[[#This Row],[Remise (%)]] -> 38.097 | K3: =IF(CLIENTS_CHURN[[#This Row],[Duree_Cumulee_Panne_Min]]>0,1,0) -> 1 | L3: =IF(CLIENTS_CHURN[[#This Row],[Type_Forfait]]="Pro Monde","B2B","B2C") -> B2B
A4: =A3+1 -> 3 | B4: CLI-00011 | C4: Mongala | D4: 49 | E4: Illimité 50Go | F4: 86 | G4: 65.4 | H4: 2 | I4: =IF(AND(CLIENTS_CHURN[[#This Row],[Duree_Cumulee_Panne_Min]]>720,CLIENTS_CHURN[[#This Row],[Anciennete_Mois]]>60),"70%",IF(OR(AND(CLIENTS_CHURN[[#This Row],[Duree_Cumulee_Panne_Min]]>=240,CLIENTS_CHURN[[#This Row],[Duree_Cumulee_Panne_Min]]<=720),AND(CLIENTS_CHURN[[#This Row],[Anciennete_Mois]]<60,CLIENTS_CHURN[[#This Row],[Type_Forfait]]="Premium")),"45%",IF(CLIENTS_CHURN[[#This Row],[Type_Forfait]]="Pro Monde","10%","0"))) -> 0 | J4: =CLIENTS_CHURN[[#This Row],[Facture_Mensuelle]]*CLIENTS_CHURN[[#This Row],[Remise (%)]] -> 0 | K4: =IF(CLIENTS_CHURN[[#This Row],[Duree_Cumulee_Panne_Min]]>0,1,0) -> 1 | L4: =IF(CLIENTS_CHURN[[#This Row],[Type_Forfait]]="Pro Monde","B2B","B2C") -> B2C
A5: =A4+1 -> 4 | B5: CLI-00012 | C5: Kongo-Central | D5: 105 | E5: Illimité 50Go | F5: 172 | G5: 15.88 | H5: 5 | I5: =IF(AND(CLIENTS_CHURN[[#This Row],[Duree_Cumulee_Panne_Min]]>720,CLIENTS_CHURN[[#This Row],[Anciennete_Mois]]>60),"70%",IF(OR(AND(CLIENTS_CHURN[[#This Row],[Duree_Cumulee_Panne_Min]]>=240,CLIENTS_CHURN[[#This Row],[Duree_Cumulee_Panne_Min]]<=720),AND(CLIENTS_CHURN[[#This Row],[Anciennete_Mois]]<60,CLIENTS_CHURN[[#This Row],[Type_Forfait]]="Premium")),"45%",IF(CLIENTS_CHURN[[#This Row],[Type_Forfait]]="Pro Monde","10%","0"))) -> 0 | J5: =CLIENTS_CHURN[[#This Row],[Facture_Mensuelle]]*CLIENTS_CHURN[[#This Row],[Remise (%)]] -> 0 | K5: =IF(CLIENTS_CHURN[[#This Row],[Duree_Cumulee_Panne_Min]]>0,1,0) -> 1 | L5: =IF(CLIENTS_CHURN[[#This Row],[Type_Forfait]]="Pro Monde","B2B","B2C") -> B2C
A6: =A5+1 -> 5 | B6: CLI-00017 | C6: Tanganyika | D6: 29 | E6: Illimité 50Go | F6: 124 | G6: 43.83 | H6: 5 | I6: =IF(AND(CLIENTS_CHURN[[#This Row],[Duree_Cumulee_Panne_Min]]>720,CLIENTS_CHURN[[#This Row],[Anciennete_Mois]]>60),"70%",IF(OR(AND(CLIENTS_CHURN[[#This Row],[Duree_Cumulee_Panne_Min]]>=240,CLIENTS_CHURN[[#This Row],[Duree_Cumulee_Panne_Min]]<=720),AND(CLIENTS_CHURN[[#This Row],[Anciennete_Mois]]<60,CLIENTS_CHURN[[#This Row],[Type_Forfait]]="Premium")),"45%",IF(CLIENTS_CHURN[[#This Row],[Type_Forfait]]="Pro Monde","10%","0"))) -> 0 | J6: =CLIENTS_CHURN[[#This Row],[Facture_Mensuelle]]*CLIENTS_CHURN[[#This Row],[Remise (%)]] -> 0 | K6: =IF(CLIENTS_CHURN[[#This Row],[Duree_Cumulee_Panne_Min]]>0,1,0) -> 1 | L6: =IF(CLIENTS_CHURN[[#This Row],[Type_Forfait]]="Pro Monde","B2B","B2C") -> B2C
A7: =A6+1 -> 6 | B7: CLI-00022 | C7: Haut-Lomami | D7: 77 | E7: Premium 5G 150Go | F7: 488 | G7: 21.17 | H7: 0 | I7: =IF(AND(CLIENTS_CHURN[[#This Row],[Duree_Cumulee_Panne_Min]]>720,CLIENTS_CHURN[[#This Row],[Anciennete_Mois]]>60),"70%",IF(OR(AND(CLIENTS_CHURN[[#This Row],[Duree_Cumulee_Panne_Min]]>=240,CLIENTS_CHURN[[#This Row],[Duree_Cumulee_Panne_Min]]<=720),AND(CLIENTS_CHURN[[#This Row],[Anciennete_Mois]]<60,CLIENTS_CHURN[[#This Row],[Type_Forfait]]="Premium")),"45%",IF(CLIENTS_CHURN[[#This Row],[Type_Forfait]]="Pro Monde","10%","0"))) -> 45% | J7: =CLIENTS_CHURN[[#This Row],[Facture_Mensuelle]]*CLIENTS_CHURN[[#This Row],[Remise (%)]] -> 9.5265 | K7: =IF(CLIENTS_CHURN[[#This Row],[Duree_Cumulee_Panne_Min]]>0,1,0) -> 1 | L7: =IF(CLIENTS_CHURN[[#This Row],[Type_Forfait]]="Pro Monde","B2B","B2C") -> B2C
A8: =A7+1 -> 7 | B8: CLI-00028 | C8: Kwilu | D8: 18 | E8: Pro Monde | F8: 216 | G8: 33.74 | H8: 5 | I8: =IF(AND(CLIENTS_CHURN[[#This Row],[Duree_Cumulee_Panne_Min]]>720,CLIENTS_CHURN[[#This Row],[Anciennete_Mois]]>60),"70%",IF(OR(AND(CLIENTS_CHURN[[#This Row],[Duree_Cumulee_Panne_Min]]>=240,CLIENTS_CHURN[[#This Row],[Duree_Cumulee_Panne_Min]]<=720),AND(CLIENTS_CHURN[[#This Row],[Anciennete_Mois]]<60,CLIENTS_CHURN[[#This Row],[Type_Forfait]]="Premium")),"45%",IF(CLIENTS_CHURN[[#This Row],[Type_Forfait]]="Pro Monde","10%","0"))) -> 10% | J8: =CLIENTS_CHURN[[#This Row],[Facture_Mensuelle]]*CLIENTS_CHURN[[#This Row],[Remise (%)]] -> 3.374 | K8: =IF(CLIENTS_CHURN[[#This Row],[Duree_Cumulee_Panne_Min]]>0,1,0) -> 1 | L8: =IF(CLIENTS_CHURN[[#This Row],[Type_Forfait]]="Pro Monde","B2B","B2C") -> B2B
A9: =A8+1 -> 8 | B9: CLI-00029 | C9: Bas-Uele | D9: 119 | E9: Pro Monde | F9: 344 | G9: 10.28 | H9: 0 | I9: =IF(AND(CLIENTS_CHURN[[#This Row],[Duree_Cumulee_Panne_Min]]>720,CLIENTS_CHURN[[#This Row],[Anciennete_Mois]]>60),"70%",IF(OR(AND(CLIENTS_CHURN[[#This Row],[Duree_Cumulee_Panne_Min]]>=240,CLIENTS_CHURN[[#This Row],[Duree_Cumulee_Panne_Min]]<=720),AND(CLIENTS_CHURN[[#This Row],[Anciennete_Mois]]<60,CLIENTS_CHURN[[#This Row],[Type_Forfait]]="Premium")),"45%",IF(CLIENTS_CHURN[[#This Row],[Type_Forfait]]="Pro Monde","10%","0"))) -> 45% | J9: =CLIENTS_CHURN[[#This Row],[Facture_Mensuelle]]*CLIENTS_CHURN[[#This Row],[Remise (%)]] -> 4.626 | K9: =IF(CLIENTS_CHURN[[#This Row],[Duree_Cumulee_Panne_Min]]>0,1,0) -> 1 | L9: =IF(CLIENTS_CHURN[[#This Row],[Type_Forfait]]="Pro Monde","B2B","B2C") -> B2B
A10: =A9+1 -> 9 | B10: CLI-00033 | C10: Tshuapa | D10: 2 | E10: Premium 5G 150Go | F10: 201 | G10: 71.9 | H10: 2 | I10: =IF(AND(CLIENTS_CHURN[[#This Row],[Duree_Cumulee_Panne_Min]]>720,CLIENTS_CHURN[[#This Row],[Anciennete_Mois]]>60),"70%",IF(OR(AND(CLIENTS_CHURN[[#This Row],[Duree_Cumulee_Panne_Min]]>=240,CLIENTS_CHURN[[#This Row],[Duree_Cumulee_Panne_Min]]<=720),AND(CLIENTS_CHURN[[#This Row],[Anciennete_Mois]]<60,CLIENTS_CHURN[[#This Row],[Type_Forfait]]="Premium")),"45%",IF(CLIENTS_CHURN[[#This Row],[Type_Forfait]]="Pro Monde","10%","0"))) -> 0 | J10: =CLIENTS_CHURN[[#This Row],[Facture_Mensuelle]]*CLIENTS_CHURN[[#This Row],[Remise (%)]] -> 0 | K10: =IF(CLIENTS_CHURN[[#This Row],[Duree_Cumulee_Panne_Min]]>0,1,0) -> 1 | L10: =IF(CLIENTS_CHURN[[#This Row],[Type_Forfait]]="Pro Monde","B2B","B2C") -> B2C
A11: =A10+1 -> 10 | B11: CLI-00034 | C11: Kongo-Central | D11: 25 | E11: Bloqué 5Go | F11: 95 | G11: 15.93 | H11: 4 | I11: =IF(AND(CLIENTS_CHURN[[#This Row],[Duree_Cumulee_Panne_Min]]>720,CLIENTS_CHURN[[#This Row],[Anciennete_Mois]]>60),"70%",IF(OR(AND(CLIENTS_CHURN[[#This Row],[Duree_Cumulee_Panne_Min]]>=240,CLIENTS_CHURN[[#This Row],[Duree_Cumulee_Panne_Min]]<=720),AND(CLIENTS_CHURN[[#This Row],[Anciennete_Mois]]<60,CLIENTS_CHURN[[#This Row],[Type_Forfait]]="Premium")),"45%",IF(CLIENTS_CHURN[[#This Row],[Type_Forfait]]="Pro Monde","10%","0"))) -> 0 | J11: =CLIENTS_CHURN[[#This Row],[Facture_Mensuelle]]*CLIENTS_CHURN[[#This Row],[Remise (%)]] -> 0 | K11: =IF(CLIENTS_CHURN[[#This Row],[Duree_Cumulee_Panne_Min]]>0,1,0) -> 1 | L11: =IF(CLIENTS_CHURN[[#This Row],[Type_Forfait]]="Pro Monde","B2B","B2C") -> B2C
A12: =A11+1 -> 11 | B12: CLI-00037 | C12: Tanganyika | D12: 35 | E12: Premium 5G 150Go | F12: 332 | G12: 11.15 | H12: 0 | I12: =IF(AND(CLIENTS_CHURN[[#This Row],[Duree_Cumulee_Panne_Min]]>720,CLIENTS_CHURN[[#This Row],[Anciennete_Mois]]>60),"70%",IF(OR(AND(CLIENTS_CHURN[[#This Row],[Duree_Cumulee_Panne_Min]]>=240,CLIENTS_CHURN[[#This Row],[Duree_Cumulee_Panne_Min]]<=720),AND(CLIENTS_CHURN[[#This Row],[Anciennete_Mois]]<60,CLIENTS_CHURN[[#This Row],[Type_Forfait]]="Premium")),"45%",IF(CLIENTS_CHURN[[#This Row],[Type_Forfait]]="Pro Monde","10%","0"))) -> 45% | J12: =CLIENTS_CHURN[[#This Row],[Facture_Mensuelle]]*CLIENTS_CHURN[[#This Row],[Remise (%)]] -> 5.0175 | K12: =IF(CLIENTS_CHURN[[#This Row],[Duree_Cumulee_Panne_Min]]>0,1,0) -> 1 | L12: =IF(CLIENTS_CHURN[[#This Row],[Type_Forfait]]="Pro Monde","B2B","B2C") -> B2C
A13: =A12+1 -> 12 | B13: CLI-00039 | C13: Maniema | D13: 119 | E13: Pro Monde | F13: 31 | G13: 21.27 | H13: 5 | I13: =IF(AND(CLIENTS_CHURN[[#This Row],[Duree_Cumulee_Panne_Min]]>720,CLIENTS_CHURN[[#This Row],[Anciennete_Mois]]>60),"70%",IF(OR(AND(CLIENTS_CHURN[[#This Row],[Duree_Cumulee_Panne_Min]]>=240,CLIENTS_CHURN[[#This Row],[Duree_Cumulee_Panne_Min]]<=720),AND(CLIENTS_CHURN[[#This Row],[Anciennete_Mois]]<60,CLIENTS_CHURN[[#This Row],[Type_Forfait]]="Premium")),"45%",IF(CLIENTS_CHURN[[#This Row],[Type_Forfait]]="Pro Monde","10%","0"))) -> 10% | J13: =CLIENTS_CHURN[[#This Row],[Facture_Mensuelle]]*CLIENTS_CHURN[[#This Row],[Remise (%)]] -> 2.127 | K13: =IF(CLIENTS_CHURN[[#This Row],[Duree_Cumulee_Panne_Min]]>0,1,0) -> 1 | L13: =IF(CLIENTS_CHURN[[#This Row],[Type_Forfait]]="Pro Monde","B2B","B2C") -> B2B
A14: =A13+1 -> 13 | B14: CLI-00041 | C14: Ituri | D14: 103 | E14: Pro Monde | F14: 105 | G14: 61.52 | H14: 3 | I14: =IF(AND(CLIENTS_CHURN[[#This Row],[Duree_Cumulee_Panne_Min]]>720,CLIENTS_CHURN[[#This Row],[Anciennete_Mois]]>60),"70%",IF(OR(AND(CLIENTS_CHURN[[#This Row],[Duree_Cumulee_Panne_Min]]>=240,CLIENTS_CHURN[[#This Row],[Duree_Cumulee_Panne_Min]]<=720),AND(CLIENTS_CHURN[[#This Row],[Anciennete_Mois]]<60,CLIENTS_CHURN[[#This Row],[Type_Forfait]]="Premium")),"45%",IF(CLIENTS_CHURN[[#This Row],[Type_Forfait]]="Pro Monde","10%","0"))) -> 10% | J14: =CLIENTS_CHURN[[#This Row],[Facture_Mensuelle]]*CLIENTS_CHURN[[#This Row],[Remise (%)]] -> 6.152 | K14: =IF(CLIENTS_CHURN[[#This Row],[Duree_Cumulee_Panne_Min]]>0,1,0) -> 1 | L14: =IF(CLIENTS_CHURN[[#This Row],[Type_Forfait]]="Pro Monde","B2B","B2C") -> B2B
... A751: =A750+1 -> 750 | B751: CLI-01999 | C751: Sud-Ubangi | D751: 47 | E751: Pro Monde | F751: 149 | G751: 28.35 | H751: 1 | I751: =IF(AND(CLIENTS_CHURN[[#This Row],[Duree_Cumulee_Panne_Min]]>720,CLIENTS_CHURN[[#This Row],[Anciennete_Mois]]>60),"70%",IF(OR(AND(CLIENTS_CHURN[[#This Row],[Duree_Cumulee_Panne_Min]]>=240,CLIENTS_CHURN[[#This Row],[Duree_Cumulee_Panne_Min]]<=720),AND(CLIENTS_CHURN[[#This Row],[Anciennete_Mois]]<60,CLIENTS_CHURN[[#This Row],[Type_Forfait]]="Premium")),"45%",IF(CLIENTS_CHURN[[#This Row],[Type_Forfait]]="Pro Monde","10%","0"))) -> 10% | J751: =CLIENTS_CHURN[[#This Row],[Facture_Mensuelle]]*CLIENTS_CHURN[[#This Row],[Remise (%)]] -> 2.835 | K751: =IF(CLIENTS_CHURN[[#This Row],[Duree_Cumulee_Panne_Min]]>0,1,0) -> 1 | L751: =IF(CLIENTS_CHURN[[#This Row],[Type_Forfait]]="Pro Monde","B2B","B2C") -> B2B

Sheet Clients_Churn suite
A1: ID_Client | B1: Province_Client | C1: Anciennete_Mois | D1: Type_Forfait | E1: Duree_Cumulee_Panne_Min | F1: Facture_Mensuelle | G1: Plaintes_Service_Client | H1: Remise (%) | I1: Perte_Financiere | J1: Client_Impacte
A2: CLI-01998 | B2: Tshopo | C2: 7 | D2: Pro Monde | E2: 332 | F2: 83.95 | G2: 4 | H2: 45% | I2: 37.7775 | J2: 1
A3: CLI-01940 | B3: Tshopo | C3: 104 | D3: Premium 5G 150Go | E3: 68 | F3: 21.15 | G3: 2 | H3: 0 | I3: 0 | J3: 1
A4: CLI-01911 | B4: Tshopo | C4: 58 | D4: Illimité 50Go | E4: 61 | F4: 58.64 | G4: 3 | H4: 0 | I4: 0 | J4: 1
A5: CLI-01854 | B5: Tshopo | C5: 16 | D5: Bloqué 5Go | E5: 13 | F5: 14.91 | G5: 1 | H5: 0 | I5: 0 | J5: 1
A6: CLI-01796 | B6: Tshopo | C6: 51 | D6: Illimité 50Go | E6: 433 | F6: 12.89 | G6: 1 | H6: 45% | I6: 5.8005 | J6: 1
A7: CLI-01765 | B7: Tshopo | C7: 57 | D7: Illimité 50Go | E7: 375 | F7: 64.73 | G7: 1 | H7: 45% | I7: 29.1285 | J7: 1
A8: CLI-01695 | B8: Tshopo | C8: 5 | D8: Premium 5G 150Go | E8: 384 | F8: 97.26 | G8: 3 | H8: 45% | I8: 43.767 | J8: 1
A9: CLI-01666 | B9: Tshopo | C9: 11 | D9: Premium 5G 150Go | E9: 191 | F9: 87.37 | G9: 3 | H9: 0 | I9: 0 | J9: 1
A10: CLI-01565 | B10: Tshopo | C10: 24 | D10: Bloqué 5Go | E10: 257 | F10: 41.99 | G10: 5 | H10: 45% | I10: 18.8955 | J10: 1
A11: CLI-01453 | B11: Tshopo | C11: 2 | D11: Bloqué 5Go | E11: 142 | F11: 49.05 | G11: 4 | H11: 0 | I11: 0 | J11: 1
A12: CLI-01355 | B12: Tshopo | C12: 116 | D12: Premium 5G 150Go | E12: 14 | F12: 30.38 | G12: 1 | H12: 0 | I12: 0 | J12: 1
A13: CLI-01319 | B13: Tshopo | C13: 47 | D13: Premium 5G 150Go | E13: 350 | F13: 80.48 | G13: 3 | H13: 45% | I13: 36.216 | J13: 1
... A27: CLI-00100 | B27: Tshopo | C27: 74 | D27: Bloqué 5Go | E27: 388 | F27: 10.89 | G27: 4 | H27: 45% | I27: 4.9005 | J27: 1

Sheet Logs et Registre suite
A1: Cell_ID | B1: Date_Heure_Panne | C1: Duree_Panne_Min | D1: Statut_Resolution | E1: Province_RDC | F1: Latitude | G1: Longitude | H1: Technologie | I1: Equipementier | J1: Statut_Data | K1: Nb_Pannes | L1: Duree_Totale_Pannes
A2: ANT-0925 | B2: 45205.831 | C2: 52 | D2: Résolu | E2: Haut-Uele | F2: -2.219956 | G2: 22.614449 | H2: 3G | I2: Nokia | J2: OK | K2: 1 | L2: 52
A3: ANT-0865 | B3: 45210.69 | C3: 16 | D3: Résolu | E3: Haut-Uele | F3: -4.869434 | G3: 22.326522 | H3: 5G | I3: Ericsson | J3: OK | K3: 2 | L3: 92
A4: ANT-0865 | B4: 45204.986 | C4: 76 | D4: Non Résolu | E4: Haut-Uele | F4: -4.869434 | G4: 22.326522 | H4: 5G | I4: Ericsson | J4: OK | K4: 2 | L4: 92
A5: ANT-0797 | B5: 45216.694 | C5: 24 | D5: En Cours | E5: Haut-Uele | F5: -12.100756 | G5: 21.93865 | H5: 4G | I5: Huawei | J5: OK | K5: 2 | L5: 100
A6: ANT-0797 | B6: 45206.688 | C6: 76 | D6: En Cours | E6: Haut-Uele | F6: -12.100756 | G6: 21.93865 | H6: 4G | I6: Huawei | J6: OK | K6: 2 | L6: 100
A7: ANT-0754 | B7: 45221.648 | C7: 67 | D7: Résolu | E7: Haut-Uele | F7: -11.924048 | G7: 24.177175 | H7: 3G | I7: Nokia | J7: OK | K7: 1 | L7: 67
A8: ANT-0696 | B8: 45211.723 | C8: 28 | D8: Résolu | E8: Haut-Uele | F8: -6.962499 | G8: 20.759835 | H8: 4G | I8: Huawei | J8: OK | K8: 1 | L8: 28
A9: ANT-0691 | B9: 45229.621 | C9: 74 | D9: En Cours | E9: Haut-Uele | F9: -12.488033 | G9: 16.139648 | H9: 4G | I9: Huawei | J9: OK | K9: 1 | L9: 74
A10: ANT-0670 | B10: 45211.889 | C10: 87 | D10: Non Résolu | E10: Haut-Uele | F10: -7.148375 | G10: 26.014271 | H10: 5G | I10: Huawei | J10: OK | K10: 3 | L10: 291
A11: ANT-0670 | B11: 45219.527 | C11: 95 | D11: Résolu | E11: Haut-Uele | F11: -7.148375 | G11: 26.014271 | H11: 5G | I11: Huawei | J11: OK | K11: 3 | L11: 291
A12: ANT-0670 | B12: 45202.529 | C12: 109 | D12: Non Résolu | E12: Haut-Uele | F12: -7.148375 | G12: 26.014271 | H12: 5G | I12: Huawei | J12: OK | K12: 3 | L12: 291
A13: ANT-0622 | B13: 45217.756 | C13: 100 | D13: Résolu | E13: Haut-Uele | F13: -3.003879 | G13: 23.633893 | H13: 5G | I13: Ericsson | J13: OK | K13: 1 | L13: 100
... A40: ANT-0101 | B40: 45226.077 | C40: 60 | D40: Résolu | E40: Haut-Uele | F40: 1.013488 | G40: 20.363515 | H40: 4G | I40: Nokia | J40: OK | K40: 5 | L40: 312

Sheet TDC CLIENTS, LOGS, REGISTRE 
A3: Somme de Duree_Totale_Pannes | I3: Somme de Client_Impacte | J3: Somme de Perte_Financiere | M3: Moyenne de Nb_Pannes
B4: 3G | C4: 4G | D4: 5G | E4: Total général | H4: Kwango | I4: 30 | J4: 593.0665 | L4: Sud-Ubangi | M4: 5.9166667
A5: Sud-Kivu | B5: 11511 | C5: 410 | D5: 5123 | E5: 17044 | H5: Nord-Kivu | I5: 34 | J5: 580.17 | L5: Nord-Ubangi | M5: 5.6666667
A6: Sud-Ubangi | B6: 4330 | C6: 935 | D6: 11414 | E6: 16679 | H6: Kasai-Central | I6: 27 | J6: 550.498 | L6: Mai-Ndombe | M6: 5.64
A7: Kongo-Central | B7: 921 | C7: 4988 | D7: 9816 | E7: 15725 | H7: Bas-Uele | I7: 33 | J7: 550.2105 | L7: Equateur | M7: 5.0555556
A8: Nord-Kivu | B8: 5714 | C8: 1919 | D8: 7095 | E8: 14728 | H8: Haut-Katanga | I8: 38 | J8: 514.032 | L8: Sud-Kivu | M8: 4.7358491
A9: Nord-Ubangi | B9: 3460 | C9: 3230 | D9: 6839 | E9: 13529 | H9: Ituri | I9: 37 | J9: 481.226 | L9: Non trouvé | M9: 4.612426
A10: Bas-Uele | B10: 2020 | C10: 7465 | D10: 2590 | E10: 12075 | H10: Haut-Lomami | I10: 33 | J10: 459.3475 | L10: Ituri | M10: 4.5625
A11: Maniema | C11: 9358 | D11: 2007 | E11: 11365 | H11: Nord-Ubangi | I11: 28 | J11: 427.56 | L11: Maniema | M11: 4.3658537
A12: Equateur | B12: 5374 | C12: 1804 | D12: 4088 | E12: 11266 | H12: Kwilu | I12: 39 | J12: 427.169 | L12: Bas-Uele | M12: 4.3658537
A13: Tshopo | B13: 2701 | C13: 4277 | D13: 2974 | E13: 9952 | H13: Kasai | I13: 27 | J13: 416.9015 | L13: Kongo-Central | M13: 4.36
A14: Haut-Uele | B14: 963 | C14: 2237 | D14: 6351 | E14: 9551 | H14: Sud-Ubangi | I14: 32 | J14: 416.2285 | L14: Haut-Uele | M14: 4.1282051
A15: Ituri | B15: 4087 | C15: 2844 | D15: 2574 | E15: 9505 | H15: Mai-Ndombe | I15: 33 | J15: 406.1715 | L15: Kasai-Central | M15: 4.1176471
A16: Tanganyika | B16: 1605 | C16: 5011 | D16: 2884 | E16: 9500 | H16: Tanganyika | I16: 30 | J16: 372.547 | L16: Kasai | M16: 4.0666667
A17: Haut-Katanga | B17: 4479 | C17: 2106 | D17: 1727 | E17: 8312 | H17: Tshuapa | I17: 27 | J17: 370.269 | L17: Tshuapa | M17: 4
A18: Kasai | B18: 674 | C18: 2462 | D18: 4279 | E18: 7415 | H18: Kasai-Oriental | I18: 30 | J18: 369.825 | L18: Nord-Kivu | M18: 3.9206349
A19: Lualaba | B19: 932 | C19: 5725 | D19: 628 | E19: 7285 | H19: Maniema | I19: 26 | J19: 363.5775 | L19: Tshopo | M19: 3.85
A20: Kasai-Central | B20: 3652 | C20: 1001 | D20: 2512 | E20: 7165 | H20: Equateur | I20: 24 | J20: 362.5135 | L20: Haut-Lomami | M20: 3.7272727
A21: Tshuapa | B21: 500 | C21: 5622 | D21: 1040 | E21: 7162 | H21: Sankuru | I21: 32 | J21: 308.8465 | L21: Tanganyika | M21: 3.6
A22: Haut-Lomami | B22: 1031 | C22: 5592 | D22: 393 | E22: 7016 | H22: Mongala | I22: 30 | J22: 303.4415 | L22: Mongala | M22: 3.5454545
A23: Mai-Ndombe | B23: 139 | C23: 6491 | D23: 178 | E23: 6808 | H23: Tshopo | I23: 26 | J23: 298.1415 | L23: Kinshasa | M23: 3.5333333
... A30: Kasai-Oriental | B30: 249 | C30: 424 | D30: 1419 | E30: 2092 | H30: Total général | I30: 750 | J30: 9936.6105 | L30: Lomami | M30: 2
A31: Total général | B31: 65627 | C31: 82453 | D31: 85345 | E31: 233425 | L31: Total général | M31: 4.371888

Sheet Logs et Registre 
A1: Cell_ID | B1: Date_Heure_Panne | C1: Duree_Panne_Min | D1: Statut_Resolution | E1: Province_RDC | F1: Latitude | G1: Longitude | H1: Technologie | I1: Equipementier | J1: Statut_Data | K1: Nb_Pannes | L1: Duree_Totale_Pannes
A2: ANT-0001 | B2: 45223.344 | C2: 74 | D2: Résolu | E2: =IFERROR(VLOOKUP(LOG_RESEAU[[#This Row],[Cell_ID]],Registre_Maintenance!A:B,2,FALSE),"Non trouvé") -> Nord-Ubangi | F2: =IFERROR(VLOOKUP(LOG_RESEAU[[#This Row],[Cell_ID]],Registre_Maintenance!A:C,3,FALSE),"Non trouvé") -> -8.143791 | G2: =IFERROR(VLOOKUP(LOG_RESEAU[[#This Row],[Cell_ID]],Registre_Maintenance!A:D,4,FALSE),"Non trouvé") -> 28.946161 | H2: =IFERROR(VLOOKUP(LOG_RESEAU[[#This Row],[Cell_ID]],Registre_Maintenance!A:E,5,FALSE),"Non trouvé") -> 4G | I2: =IFERROR(VLOOKUP(LOG_RESEAU[[#This Row],[Cell_ID]],Registre_Maintenance!A:F,6,FALSE),"Non trouvé") -> ZTE | J2: =IF(ISERROR(SEARCH("Non trouvé",F2)),"OK","Antenne inconnue") -> OK | K2: =COUNTIF(A:A,A2) -> 5 | L2: =SUMIF(A:A,A2,C:C) -> 252
A3: ANT-0001 | B3: 45220.642 | C3: 42 | D3: Non Résolu | E3: =IFERROR(VLOOKUP(LOG_RESEAU[[#This Row],[Cell_ID]],Registre_Maintenance!A:B,2,FALSE),"Non trouvé") -> Nord-Ubangi | F3: =IFERROR(VLOOKUP(LOG_RESEAU[[#This Row],[Cell_ID]],Registre_Maintenance!A:C,3,FALSE),"Non trouvé") -> -8.143791 | G3: =IFERROR(VLOOKUP(LOG_RESEAU[[#This Row],[Cell_ID]],Registre_Maintenance!A:D,4,FALSE),"Non trouvé") -> 28.946161 | H3: =IFERROR(VLOOKUP(LOG_RESEAU[[#This Row],[Cell_ID]],Registre_Maintenance!A:E,5,FALSE),"Non trouvé") -> 4G | I3: =IFERROR(VLOOKUP(LOG_RESEAU[[#This Row],[Cell_ID]],Registre_Maintenance!A:F,6,FALSE),"Non trouvé") -> ZTE | J3: =IF(ISERROR(SEARCH("Non trouvé",F3)),"OK","Antenne inconnue") -> OK | K3: =COUNTIF(A:A,A3) -> 5 | L3: =SUMIF(A:A,A3,C:C) -> 252
A4: ANT-0001 | B4: 45211.279 | C4: 75 | D4: Résolu | E4: =IFERROR(VLOOKUP(LOG_RESEAU[[#This Row],[Cell_ID]],Registre_Maintenance!A:B,2,FALSE),"Non trouvé") -> Nord-Ubangi | F4: =IFERROR(VLOOKUP(LOG_RESEAU[[#This Row],[Cell_ID]],Registre_Maintenance!A:C,3,FALSE),"Non trouvé") -> -8.143791 | G4: =IFERROR(VLOOKUP(LOG_RESEAU[[#This Row],[Cell_ID]],Registre_Maintenance!A:D,4,FALSE),"Non trouvé") -> 28.946161 | H4: =IFERROR(VLOOKUP(LOG_RESEAU[[#This Row],[Cell_ID]],Registre_Maintenance!A:E,5,FALSE),"Non trouvé") -> 4G | I4: =IFERROR(VLOOKUP(LOG_RESEAU[[#This Row],[Cell_ID]],Registre_Maintenance!A:F,6,FALSE),"Non trouvé") -> ZTE | J4: =IF(ISERROR(SEARCH("Non trouvé",F4)),"OK","Antenne inconnue") -> OK | K4: =COUNTIF(A:A,A4) -> 5 | L4: =SUMIF(A:A,A4,C:C) -> 252
A5: ANT-0001 | B5: 45205.014 | C5: 35 | D5: Non Résolu | E5: =IFERROR(VLOOKUP(LOG_RESEAU[[#This Row],[Cell_ID]],Registre_Maintenance!A:B,2,FALSE),"Non trouvé") -> Nord-Ubangi | F5: =IFERROR(VLOOKUP(LOG_RESEAU[[#This Row],[Cell_ID]],Registre_Maintenance!A:C,3,FALSE),"Non trouvé") -> -8.143791 | G5: =IFERROR(VLOOKUP(LOG_RESEAU[[#This Row],[Cell_ID]],Registre_Maintenance!A:D,4,FALSE),"Non trouvé") -> 28.946161 | H5: =IFERROR(VLOOKUP(LOG_RESEAU[[#This Row],[Cell_ID]],Registre_Maintenance!A:E,5,FALSE),"Non trouvé") -> 4G | I5: =IFERROR(VLOOKUP(LOG_RESEAU[[#This Row],[Cell_ID]],Registre_Maintenance!A:F,6,FALSE),"Non trouvé") -> ZTE | J5: =IF(ISERROR(SEARCH("Non trouvé",F5)),"OK","Antenne inconnue") -> OK | K5: =COUNTIF(A:A,A5) -> 5 | L5: =SUMIF(A:A,A5,C:C) -> 252
A6: ANT-0001 | B6: 45203.517 | C6: 26 | D6: Résolu | E6: =IFERROR(VLOOKUP(LOG_RESEAU[[#This Row],[Cell_ID]],Registre_Maintenance!A:B,2,FALSE),"Non trouvé") -> Nord-Ubangi | F6: =IFERROR(VLOOKUP(LOG_RESEAU[[#This Row],[Cell_ID]],Registre_Maintenance!A:C,3,FALSE),"Non trouvé") -> -8.143791 | G6: =IFERROR(VLOOKUP(LOG_RESEAU[[#This Row],[Cell_ID]],Registre_Maintenance!A:D,4,FALSE),"Non trouvé") -> 28.946161 | H6: =IFERROR(VLOOKUP(LOG_RESEAU[[#This Row],[Cell_ID]],Registre_Maintenance!A:E,5,FALSE),"Non trouvé") -> 4G | I6: =IFERROR(VLOOKUP(LOG_RESEAU[[#This Row],[Cell_ID]],Registre_Maintenance!A:F,6,FALSE),"Non trouvé") -> ZTE | J6: =IF(ISERROR(SEARCH("Non trouvé",F6)),"OK","Antenne inconnue") -> OK | K6: =COUNTIF(A:A,A6) -> 5 | L6: =SUMIF(A:A,A6,C:C) -> 252
A7: ANT-0002 | B7: 45200.767 | C7: 78 | D7: Résolu | E7: =IFERROR(VLOOKUP(LOG_RESEAU[[#This Row],[Cell_ID]],Registre_Maintenance!A:B,2,FALSE),"Non trouvé") -> Mai-Ndombe | F7: =IFERROR(VLOOKUP(LOG_RESEAU[[#This Row],[Cell_ID]],Registre_Maintenance!A:C,3,FALSE),"Non trouvé") -> -10.442425 | G7: =IFERROR(VLOOKUP(LOG_RESEAU[[#This Row],[Cell_ID]],Registre_Maintenance!A:D,4,FALSE),"Non trouvé") -> 23.243632 | H7: =IFERROR(VLOOKUP(LOG_RESEAU[[#This Row],[Cell_ID]],Registre_Maintenance!A:E,5,FALSE),"Non trouvé") -> 4G | I7: =IFERROR(VLOOKUP(LOG_RESEAU[[#This Row],[Cell_ID]],Registre_Maintenance!A:F,6,FALSE),"Non trouvé") -> Nokia | J7: =IF(ISERROR(SEARCH("Non trouvé",F7)),"OK","Antenne inconnue") -> OK | K7: =COUNTIF(A:A,A7) -> 6 | L7: =SUMIF(A:A,A7,C:C) -> 356
A8: ANT-0002 | B8: 45226.104 | C8: 56 | D8: Résolu | E8: =IFERROR(VLOOKUP(LOG_RESEAU[[#This Row],[Cell_ID]],Registre_Maintenance!A:B,2,FALSE),"Non trouvé") -> Mai-Ndombe | F8: =IFERROR(VLOOKUP(LOG_RESEAU[[#This Row],[Cell_ID]],Registre_Maintenance!A:C,3,FALSE),"Non trouvé") -> -10.442425 | G8: =IFERROR(VLOOKUP(LOG_RESEAU[[#This Row],[Cell_ID]],Registre_Maintenance!A:D,4,FALSE),"Non trouvé") -> 23.243632 | H8: =IFERROR(VLOOKUP(LOG_RESEAU[[#This Row],[Cell_ID]],Registre_Maintenance!A:E,5,FALSE),"Non trouvé") -> 4G | I8: =IFERROR(VLOOKUP(LOG_RESEAU[[#This Row],[Cell_ID]],Registre_Maintenance!A:F,6,FALSE),"Non trouvé") -> Nokia | J8: =IF(ISERROR(SEARCH("Non trouvé",F8)),"OK","Antenne inconnue") -> OK | K8: =COUNTIF(A:A,A8) -> 6 | L8: =SUMIF(A:A,A8,C:C) -> 356
A9: ANT-0002 | B9: 45230.153 | C9: 43 | D9: Non Résolu | E9: =IFERROR(VLOOKUP(LOG_RESEAU[[#This Row],[Cell_ID]],Registre_Maintenance!A:B,2,FALSE),"Non trouvé") -> Mai-Ndombe | F9: =IFERROR(VLOOKUP(LOG_RESEAU[[#This Row],[Cell_ID]],Registre_Maintenance!A:C,3,FALSE),"Non trouvé") -> -10.442425 | G9: =IFERROR(VLOOKUP(LOG_RESEAU[[#This Row],[Cell_ID]],Registre_Maintenance!A:D,4,FALSE),"Non trouvé") -> 23.243632 | H9: =IFERROR(VLOOKUP(LOG_RESEAU[[#This Row],[Cell_ID]],Registre_Maintenance!A:E,5,FALSE),"Non trouvé") -> 4G | I9: =IFERROR(VLOOKUP(LOG_RESEAU[[#This Row],[Cell_ID]],Registre_Maintenance!A:F,6,FALSE),"Non trouvé") -> Nokia | J9: =IF(ISERROR(SEARCH("Non trouvé",F9)),"OK","Antenne inconnue") -> OK | K9: =COUNTIF(A:A,A9) -> 6 | L9: =SUMIF(A:A,A9,C:C) -> 356
A10: ANT-0002 | B10: 45207.525 | C10: 104 | D10: Résolu | E10: =IFERROR(VLOOKUP(LOG_RESEAU[[#This Row],[Cell_ID]],Registre_Maintenance!A:B,2,FALSE),"Non trouvé") -> Mai-Ndombe | F10: =IFERROR(VLOOKUP(LOG_RESEAU[[#This Row],[Cell_ID]],Registre_Maintenance!A:C,3,FALSE),"Non trouvé") -> -10.442425 | G10: =IFERROR(VLOOKUP(LOG_RESEAU[[#This Row],[Cell_ID]],Registre_Maintenance!A:D,4,FALSE),"Non trouvé") -> 23.243632 | H10: =IFERROR(VLOOKUP(LOG_RESEAU[[#This Row],[Cell_ID]],Registre_Maintenance!A:E,5,FALSE),"Non trouvé") -> 4G | I10: =IFERROR(VLOOKUP(LOG_RESEAU[[#This Row],[Cell_ID]],Registre_Maintenance!A:F,6,FALSE),"Non trouvé") -> Nokia | J10: =IF(ISERROR(SEARCH("Non trouvé",F10)),"OK","Antenne inconnue") -> OK | K10: =COUNTIF(A:A,A10) -> 6 | L10: =SUMIF(A:A,A10,C:C) -> 356
A11: ANT-0002 | B11: 45204.296 | C11: 48 | D11: En Cours | E11: =IFERROR(VLOOKUP(LOG_RESEAU[[#This Row],[Cell_ID]],Registre_Maintenance!A:B,2,FALSE),"Non trouvé") -> Mai-Ndombe | F11: =IFERROR(VLOOKUP(LOG_RESEAU[[#This Row],[Cell_ID]],Registre_Maintenance!A:C,3,FALSE),"Non trouvé") -> -10.442425 | G11: =IFERROR(VLOOKUP(LOG_RESEAU[[#This Row],[Cell_ID]],Registre_Maintenance!A:D,4,FALSE),"Non trouvé") -> 23.243632 | H11: =IFERROR(VLOOKUP(LOG_RESEAU[[#This Row],[Cell_ID]],Registre_Maintenance!A:E,5,FALSE),"Non trouvé") -> 4G | I11: =IFERROR(VLOOKUP(LOG_RESEAU[[#This Row],[Cell_ID]],Registre_Maintenance!A:F,6,FALSE),"Non trouvé") -> Nokia | J11: =IF(ISERROR(SEARCH("Non trouvé",F11)),"OK","Antenne inconnue") -> OK | K11: =COUNTIF(A:A,A11) -> 6 | L11: =SUMIF(A:A,A11,C:C) -> 356
A12: ANT-0002 | B12: 45224.568 | C12: 27 | D12: Résolu | E12: =IFERROR(VLOOKUP(LOG_RESEAU[[#This Row],[Cell_ID]],Registre_Maintenance!A:B,2,FALSE),"Non trouvé") -> Mai-Ndombe | F12: =IFERROR(VLOOKUP(LOG_RESEAU[[#This Row],[Cell_ID]],Registre_Maintenance!A:C,3,FALSE),"Non trouvé") -> -10.442425 | G12: =IFERROR(VLOOKUP(LOG_RESEAU[[#This Row],[Cell_ID]],Registre_Maintenance!A:D,4,FALSE),"Non trouvé") -> 23.243632 | H12: =IFERROR(VLOOKUP(LOG_RESEAU[[#This Row],[Cell_ID]],Registre_Maintenance!A:E,5,FALSE),"Non trouvé") -> 4G | I12: =IFERROR(VLOOKUP(LOG_RESEAU[[#This Row],[Cell_ID]],Registre_Maintenance!A:F,6,FALSE),"Non trouvé") -> Nokia | J12: =IF(ISERROR(SEARCH("Non trouvé",F12)),"OK","Antenne inconnue") -> OK | K12: =COUNTIF(A:A,A12) -> 6 | L12: =SUMIF(A:A,A12,C:C) -> 356
A13: ANT-0003 | B13: 45200.515 | C13: 86 | D13: En Cours | E13: =IFERROR(VLOOKUP(LOG_RESEAU[[#This Row],[Cell_ID]],Registre_Maintenance!A:B,2,FALSE),"Non trouvé") -> Non trouvé | F13: =IFERROR(VLOOKUP(LOG_RESEAU[[#This Row],[Cell_ID]],Registre_Maintenance!A:C,3,FALSE),"Non trouvé") -> Non trouvé | G13: =IFERROR(VLOOKUP(LOG_RESEAU[[#This Row],[Cell_ID]],Registre_Maintenance!A:D,4,FALSE),"Non trouvé") -> Non trouvé | H13: =IFERROR(VLOOKUP(LOG_RESEAU[[#This Row],[Cell_ID]],Registre_Maintenance!A:E,5,FALSE),"Non trouvé") -> Non trouvé | I13: =IFERROR(VLOOKUP(LOG_RESEAU[[#This Row],[Cell_ID]],Registre_Maintenance!A:F,6,FALSE),"Non trouvé") -> Non trouvé | J13: =IF(ISERROR(SEARCH("Non trouvé",F13)),"OK","Antenne inconnue") -> Antenne inconnue | K13: =COUNTIF(A:A,A13) -> 4 | L13: =SUMIF(A:A,A13,C:C) -> 266
... A27: ANT-0005 | B27: 45211.235 | C27: 31 | D27: Non Résolu | E27: =IFERROR(VLOOKUP(LOG_RESEAU[[#This Row],[Cell_ID]],Registre_Maintenance!A:B,2,FALSE),"Non trouvé") -> Equateur | F27: =IFERROR(VLOOKUP(LOG_RESEAU[[#This Row],[Cell_ID]],Registre_Maintenance!A:C,3,FALSE),"Non trouvé") -> -3.544581 | G27: =IFERROR(VLOOKUP(LOG_RESEAU[[#This Row],[Cell_ID]],Registre_Maintenance!A:D,4,FALSE),"Non trouvé") -> 14.776605 | H27: =IFERROR(VLOOKUP(LOG_RESEAU[[#This Row],[Cell_ID]],Registre_Maintenance!A:E,5,FALSE),"Non trouvé") -> 4G | I27: =IFERROR(VLOOKUP(LOG_RESEAU[[#This Row],[Cell_ID]],Registre_Maintenance!A:F,6,FALSE),"Non trouvé") -> Nokia | J27: =IF(ISERROR(SEARCH("Non trouvé",F27)),"OK","Antenne inconnue") -> OK | K27: =COUNTIF(A:A,A27) -> 6 | L27: =SUMIF(A:A,A27,C:C) -> 281
B28: 45201.885 | C28: 54 | D28: Résolu | E28: =IFERROR(VLOOKUP(LOG_RESEAU[[#This Row],[Cell_ID]],Registre_Maintenance!A:B,2,FALSE),"Non trouvé") -> Non trouvé | F28: =IFERROR(VLOOKUP(LOG_RESEAU[[#This Row],[Cell_ID]],Registre_Maintenance!A:C,3,FALSE),"Non trouvé") -> Non trouvé | G28: =IFERROR(VLOOKUP(LOG_RESEAU[[#This Row],[Cell_ID]],Registre_Maintenance!A:D,4,FALSE),"Non trouvé") -> Non trouvé | H28: =IFERROR(VLOOKUP(LOG_RESEAU[[#This Row],[Cell_ID]],Registre_Maintenance!A:E,5,FALSE),"Non trouvé") -> Non trouvé | I28: =IFERROR(VLOOKUP(LOG_RESEAU[[#This Row],[Cell_ID]],Registre_Maintenance!A:F,6,FALSE),"Non trouvé") -> Non trouvé | J28: =IF(ISERROR(SEARCH("Non trouvé",F28)),"OK","Antenne inconnue") -> Antenne inconnue | K28: =COUNTIF(A:A,A28) -> 0 | L28: =SUMIF(A:A,A28,C:C) -> 0
A29: ANT-0005 | B29: 45230.053 | C29: 91 | D29: En Cours | E29: =IFERROR(VLOOKUP(LOG_RESEAU[[#This Row],[Cell_ID]],Registre_Maintenance!A:B,2,FALSE),"Non trouvé") -> Equateur | F29: =IFERROR(VLOOKUP(LOG_RESEAU[[#This Row],[Cell_ID]],Registre_Maintenance!A:C,3,FALSE),"Non trouvé") -> -3.544581 | G29: =IFERROR(VLOOKUP(LOG_RESEAU[[#This Row],[Cell_ID]],Registre_Maintenance!A:D,4,FALSE),"Non trouvé") -> 14.776605 | H29: =IFERROR(VLOOKUP(LOG_RESEAU[[#This Row],[Cell_ID]],Registre_Maintenance!A:E,5,FALSE),"Non trouvé") -> 4G | I29: =IFERROR(VLOOKUP(LOG_RESEAU[[#This Row],[Cell_ID]],Registre_Maintenance!A:F,6,FALSE),"Non trouvé") -> Nokia | J29: =IF(ISERROR(SEARCH("Non trouvé",F29)),"OK","Antenne inconnue") -> OK | K29: =COUNTIF(A:A,A29) -> 6 | L29: =SUMIF(A:A,A29,C:C) -> 281
A30: ANT-0006 | B30: 45204.339 | C30: 18 | D30: Résolu | E30: =IFERROR(VLOOKUP(LOG_RESEAU[[#This Row],[Cell_ID]],Registre_Maintenance!A:B,2,FALSE),"Non trouvé") -> Bas-Uele | F30: =IFERROR(VLOOKUP(LOG_RESEAU[[#This Row],[Cell_ID]],Registre_Maintenance!A:C,3,FALSE),"Non trouvé") -> -2.853287 | G30: =IFERROR(VLOOKUP(LOG_RESEAU[[#This Row],[Cell_ID]],Registre_Maintenance!A:D,4,FALSE),"Non trouvé") -> 22.117896 | H30: =IFERROR(VLOOKUP(LOG_RESEAU[[#This Row],[Cell_ID]],Registre_Maintenance!A:E,5,FALSE),"Non trouvé") -> 5G | I30: =IFERROR(VLOOKUP(LOG_RESEAU[[#This Row],[Cell_ID]],Registre_Maintenance!A:F,6,FALSE),"Non trouvé") -> Huawei | J30: =IF(ISERROR(SEARCH("Non trouvé",F30)),"OK","Antenne inconnue") -> OK | K30: =COUNTIF(A:A,A30) -> 3 | L30: =SUMIF(A:A,A30,C:C) -> 132
A31: ANT-0006 | B31: 45230.868 | C31: 103 | D31: En Cours | E31: =IFERROR(VLOOKUP(LOG_RESEAU[[#This Row],[Cell_ID]],Registre_Maintenance!A:B,2,FALSE),"Non trouvé") -> Bas-Uele | F31: =IFERROR(VLOOKUP(LOG_RESEAU[[#This Row],[Cell_ID]],Registre_Maintenance!A:C,3,FALSE),"Non trouvé") -> -2.853287 | G31: =IFERROR(VLOOKUP(LOG_RESEAU[[#This Row],[Cell_ID]],Registre_Maintenance!A:D,4,FALSE),"Non trouvé") -> 22.117896 | H31: =IFERROR(VLOOKUP(LOG_RESEAU[[#This Row],[Cell_ID]],Registre_Maintenance!A:E,5,FALSE),"Non trouvé") -> 5G | I31: =IFERROR(VLOOKUP(LOG_RESEAU[[#This Row],[Cell_ID]],Registre_Maintenance!A:F,6,FALSE),"Non trouvé") -> Huawei | J31: =IF(ISERROR(SEARCH("Non trouvé",F31)),"OK","Antenne inconnue") -> OK | K31: =COUNTIF(A:A,A31) -> 3 | L31: =SUMIF(A:A,A31,C:C) -> 132
A32: ANT-0006 | B32: 45230.429 | C32: 11 | D32: En Cours | E32: =IFERROR(VLOOKUP(LOG_RESEAU[[#This Row],[Cell_ID]],Registre_Maintenance!A:B,2,FALSE),"Non trouvé") -> Bas-Uele | F32: =IFERROR(VLOOKUP(LOG_RESEAU[[#This Row],[Cell_ID]],Registre_Maintenance!A:C,3,FALSE),"Non trouvé") -> -2.853287 | G32: =IFERROR(VLOOKUP(LOG_RESEAU[[#This Row],[Cell_ID]],Registre_Maintenance!A:D,4,FALSE),"Non trouvé") -> 22.117896 | H32: =IFERROR(VLOOKUP(LOG_RESEAU[[#This Row],[Cell_ID]],Registre_Maintenance!A:E,5,FALSE),"Non trouvé") -> 5G | I32: =IFERROR(VLOOKUP(LOG_RESEAU[[#This Row],[Cell_ID]],Registre_Maintenance!A:F,6,FALSE),"Non trouvé") -> Huawei | J32: =IF(ISERROR(SEARCH("Non trouvé",F32)),"OK","Antenne inconnue") -> OK | K32: =COUNTIF(A:A,A32) -> 3 | L32: =SUMIF(A:A,A32,C:C) -> 132
A33: ANT-0007 | B33: 45210.742 | C33: 19 | D33: Résolu | E33: =IFERROR(VLOOKUP(LOG_RESEAU[[#This Row],[Cell_ID]],Registre_Maintenance!A:B,2,FALSE),"Non trouvé") -> Tshopo | F33: =IFERROR(VLOOKUP(LOG_RESEAU[[#This Row],[Cell_ID]],Registre_Maintenance!A:C,3,FALSE),"Non trouvé") -> 4.777735 | G33: =IFERROR(VLOOKUP(LOG_RESEAU[[#This Row],[Cell_ID]],Registre_Maintenance!A:D,4,FALSE),"Non trouvé") -> 16.392204 | H33: =IFERROR(VLOOKUP(LOG_RESEAU[[#This Row],[Cell_ID]],Registre_Maintenance!A:E,5,FALSE),"Non trouvé") -> 5G | I33: =IFERROR(VLOOKUP(LOG_RESEAU[[#This Row],[Cell_ID]],Registre_Maintenance!A:F,6,FALSE),"Non trouvé") -> ZTE | J33: =IF(ISERROR(SEARCH("Non trouvé",F33)),"OK","Antenne inconnue") -> OK | K33: =COUNTIF(A:A,A33) -> 4 | L33: =SUMIF(A:A,A33,C:C) -> 250
A34: ANT-0007 | B34: 45226.624 | C34: 103 | D34: Résolu | E34: =IFERROR(VLOOKUP(LOG_RESEAU[[#This Row],[Cell_ID]],Registre_Maintenance!A:B,2,FALSE),"Non trouvé") -> Tshopo | F34: =IFERROR(VLOOKUP(LOG_RESEAU[[#This Row],[Cell_ID]],Registre_Maintenance!A:C,3,FALSE),"Non trouvé") -> 4.777735 | G34: =IFERROR(VLOOKUP(LOG_RESEAU[[#This Row],[Cell_ID]],Registre_Maintenance!A:D,4,FALSE),"Non trouvé") -> 16.392204 | H34: =IFERROR(VLOOKUP(LOG_RESEAU[[#This Row],[Cell_ID]],Registre_Maintenance!A:E,5,FALSE),"Non trouvé") -> 5G | I34: =IFERROR(VLOOKUP(LOG_RESEAU[[#This Row],[Cell_ID]],Registre_Maintenance!A:F,6,FALSE),"Non trouvé") -> ZTE | J34: =IF(ISERROR(SEARCH("Non trouvé",F34)),"OK","Antenne inconnue") -> OK | K34: =COUNTIF(A:A,A34) -> 4 | L34: =SUMIF(A:A,A34,C:C) -> 250
A35: ANT-0007 | B35: 45207.14 | C35: 41 | D35: Résolu | E35: =IFERROR(VLOOKUP(LOG_RESEAU[[#This Row],[Cell_ID]],Registre_Maintenance!A:B,2,FALSE),"Non trouvé") -> Tshopo | F35: =IFERROR(VLOOKUP(LOG_RESEAU[[#This Row],[Cell_ID]],Registre_Maintenance!A:C,3,FALSE),"Non trouvé") -> 4.777735 | G35: =IFERROR(VLOOKUP(LOG_RESEAU[[#This Row],[Cell_ID]],Registre_Maintenance!A:D,4,FALSE),"Non trouvé") -> 16.392204 | H35: =IFERROR(VLOOKUP(LOG_RESEAU[[#This Row],[Cell_ID]],Registre_Maintenance!A:E,5,FALSE),"Non trouvé") -> 5G | I35: =IFERROR(VLOOKUP(LOG_RESEAU[[#This Row],[Cell_ID]],Registre_Maintenance!A:F,6,FALSE),"Non trouvé") -> ZTE | J35: =IF(ISERROR(SEARCH("Non trouvé",F35)),"OK","Antenne inconnue") -> OK | K35: =COUNTIF(A:A,A35) -> 4 | L35: =SUMIF(A:A,A35,C:C) -> 250
A36: ANT-0007 | B36: 45221.566 | C36: 87 | D36: Non Résolu | E36: =IFERROR(VLOOKUP(LOG_RESEAU[[#This Row],[Cell_ID]],Registre_Maintenance!A:B,2,FALSE),"Non trouvé") -> Tshopo | F36: =IFERROR(VLOOKUP(LOG_RESEAU[[#This Row],[Cell_ID]],Registre_Maintenance!A:C,3,FALSE),"Non trouvé") -> 4.777735 | G36: =IFERROR(VLOOKUP(LOG_RESEAU[[#This Row],[Cell_ID]],Registre_Maintenance!A:D,4,FALSE),"Non trouvé") -> 16.392204 | H36: =IFERROR(VLOOKUP(LOG_RESEAU[[#This Row],[Cell_ID]],Registre_Maintenance!A:E,5,FALSE),"Non trouvé") -> 5G | I36: =IFERROR(VLOOKUP(LOG_RESEAU[[#This Row],[Cell_ID]],Registre_Maintenance!A:F,6,FALSE),"Non trouvé") -> ZTE | J36: =IF(ISERROR(SEARCH("Non trouvé",F36)),"OK","Antenne inconnue") -> OK | K36: =COUNTIF(A:A,A36) -> 4 | L36: =SUMIF(A:A,A36,C:C) -> 250
A37: ANT-0008 | B37: 45210.803 | C37: 52 | D37: Non Résolu | E37: =IFERROR(VLOOKUP(LOG_RESEAU[[#This Row],[Cell_ID]],Registre_Maintenance!A:B,2,FALSE),"Non trouvé") -> Haut-Lomami | F37: =IFERROR(VLOOKUP(LOG_RESEAU[[#This Row],[Cell_ID]],Registre_Maintenance!A:C,3,FALSE),"Non trouvé") -> -11.89448 | G37: =IFERROR(VLOOKUP(LOG_RESEAU[[#This Row],[Cell_ID]],Registre_Maintenance!A:D,4,FALSE),"Non trouvé") -> 19.216215 | H37: =IFERROR(VLOOKUP(LOG_RESEAU[[#This Row],[Cell_ID]],Registre_Maintenance!A:E,5,FALSE),"Non trouvé") -> 3G | I37: =IFERROR(VLOOKUP(LOG_RESEAU[[#This Row],[Cell_ID]],Registre_Maintenance!A:F,6,FALSE),"Non trouvé") -> ZTE | J37: =IF(ISERROR(SEARCH("Non trouvé",F37)),"OK","Antenne inconnue") -> OK | K37: =COUNTIF(A:A,A37) -> 4 | L37: =SUMIF(A:A,A37,C:C) -> 203
A38: ANT-0008 | B38: 45216.101 | C38: 98 | D38: Non Résolu | E38: =IFERROR(VLOOKUP(LOG_RESEAU[[#This Row],[Cell_ID]],Registre_Maintenance!A:B,2,FALSE),"Non trouvé") -> Haut-Lomami | F38: =IFERROR(VLOOKUP(LOG_RESEAU[[#This Row],[Cell_ID]],Registre_Maintenance!A:C,3,FALSE),"Non trouvé") -> -11.89448 | G38: =IFERROR(VLOOKUP(LOG_RESEAU[[#This Row],[Cell_ID]],Registre_Maintenance!A:D,4,FALSE),"Non trouvé") -> 19.216215 | H38: =IFERROR(VLOOKUP(LOG_RESEAU[[#This Row],[Cell_ID]],Registre_Maintenance!A:E,5,FALSE),"Non trouvé") -> 3G | I38: =IFERROR(VLOOKUP(LOG_RESEAU[[#This Row],[Cell_ID]],Registre_Maintenance!A:F,6,FALSE),"Non trouvé") -> ZTE | J38: =IF(ISERROR(SEARCH("Non trouvé",F38)),"OK","Antenne inconnue") -> OK | K38: =COUNTIF(A:A,A38) -> 4 | L38: =SUMIF(A:A,A38,C:C) -> 203
A39: ANT-0008 | B39: 45225.172 | C39: 14 | D39: Résolu | E39: =IFERROR(VLOOKUP(LOG_RESEAU[[#This Row],[Cell_ID]],Registre_Maintenance!A:B,2,FALSE),"Non trouvé") -> Haut-Lomami | F39: =IFERROR(VLOOKUP(LOG_RESEAU[[#This Row],[Cell_ID]],Registre_Maintenance!A:C,3,FALSE),"Non trouvé") -> -11.89448 | G39: =IFERROR(VLOOKUP(LOG_RESEAU[[#This Row],[Cell_ID]],Registre_Maintenance!A:D,4,FALSE),"Non trouvé") -> 19.216215 | H39: =IFERROR(VLOOKUP(LOG_RESEAU[[#This Row],[Cell_ID]],Registre_Maintenance!A:E,5,FALSE),"Non trouvé") -> 3G | I39: =IFERROR(VLOOKUP(LOG_RESEAU[[#This Row],[Cell_ID]],Registre_Maintenance!A:F,6,FALSE),"Non trouvé") -> ZTE | J39: =IF(ISERROR(SEARCH("Non trouvé",F39)),"OK","Antenne inconnue") -> OK | K39: =COUNTIF(A:A,A39) -> 4 | L39: =SUMIF(A:A,A39,C:C) -> 203
A40: ANT-0008 | B40: 45222.501 | C40: 39 | D40: Résolu | E40: =IFERROR(VLOOKUP(LOG_RESEAU[[#This Row],[Cell_ID]],Registre_Maintenance!A:B,2,FALSE),"Non trouvé") -> Haut-Lomami | F40: =IFERROR(VLOOKUP(LOG_RESEAU[[#This Row],[Cell_ID]],Registre_Maintenance!A:C,3,FALSE),"Non trouvé") -> -11.89448 | G40: =IFERROR(VLOOKUP(LOG_RESEAU[[#This Row],[Cell_ID]],Registre_Maintenance!A:D,4,FALSE),"Non trouvé") -> 19.216215 | H40: =IFERROR(VLOOKUP(LOG_RESEAU[[#This Row],[Cell_ID]],Registre_Maintenance!A:E,5,FALSE),"Non trouvé") -> 3G | I40: =IFERROR(VLOOKUP(LOG_RESEAU[[#This Row],[Cell_ID]],Registre_Maintenance!A:F,6,FALSE),"Non trouvé") -> ZTE | J40: =IF(ISERROR(SEARCH("Non trouvé",F40)),"OK","Antenne inconnue") -> OK | K40: =COUNTIF(A:A,A40) -> 4 | L40: =SUMIF(A:A,A40,C:C) -> 203
... A90: ANT-0019 | B90: 45227.728 | C90: 63 | D90: Résolu | E90: =IFERROR(VLOOKUP(LOG_RESEAU[[#This Row],[Cell_ID]],Registre_Maintenance!A:B,2,FALSE),"Non trouvé") -> Non trouvé | F90: =IFERROR(VLOOKUP(LOG_RESEAU[[#This Row],[Cell_ID]],Registre_Maintenance!A:C,3,FALSE),"Non trouvé") -> Non trouvé | G90: =IFERROR(VLOOKUP(LOG_RESEAU[[#This Row],[Cell_ID]],Registre_Maintenance!A:D,4,FALSE),"Non trouvé") -> Non trouvé | H90: =IFERROR(VLOOKUP(LOG_RESEAU[[#This Row],[Cell_ID]],Registre_Maintenance!A:E,5,FALSE),"Non trouvé") -> Non trouvé | I90: =IFERROR(VLOOKUP(LOG_RESEAU[[#This Row],[Cell_ID]],Registre_Maintenance!A:F,6,FALSE),"Non trouvé") -> Non trouvé | J90: =IF(ISERROR(SEARCH("Non trouvé",F90)),"OK","Antenne inconnue") -> Antenne inconnue | K90: =COUNTIF(A:A,A90) -> 5 | L90: =SUMIF(A:A,A90,C:C) -> 320
B91: 45223.925 | C91: 61 | D91: En Cours | E91: =IFERROR(VLOOKUP(LOG_RESEAU[[#This Row],[Cell_ID]],Registre_Maintenance!A:B,2,FALSE),"Non trouvé") -> Non trouvé | F91: =IFERROR(VLOOKUP(LOG_RESEAU[[#This Row],[Cell_ID]],Registre_Maintenance!A:C,3,FALSE),"Non trouvé") -> Non trouvé | G91: =IFERROR(VLOOKUP(LOG_RESEAU[[#This Row],[Cell_ID]],Registre_Maintenance!A:D,4,FALSE),"Non trouvé") -> Non trouvé | H91: =IFERROR(VLOOKUP(LOG_RESEAU[[#This Row],[Cell_ID]],Registre_Maintenance!A:E,5,FALSE),"Non trouvé") -> Non trouvé | I91: =IFERROR(VLOOKUP(LOG_RESEAU[[#This Row],[Cell_ID]],Registre_Maintenance!A:F,6,FALSE),"Non trouvé") -> Non trouvé | J91: =IF(ISERROR(SEARCH("Non trouvé",F91)),"OK","Antenne inconnue") -> Antenne inconnue | K91: =COUNTIF(A:A,A91) -> 0 | L91: =SUMIF(A:A,A91,C:C) -> 0
A92: ANT-0019 | B92: 45220.792 | C92: 109 | D92: Non Résolu | E92: =IFERROR(VLOOKUP(LOG_RESEAU[[#This Row],[Cell_ID]],Registre_Maintenance!A:B,2,FALSE),"Non trouvé") -> Non trouvé | F92: =IFERROR(VLOOKUP(LOG_RESEAU[[#This Row],[Cell_ID]],Registre_Maintenance!A:C,3,FALSE),"Non trouvé") -> Non trouvé | G92: =IFERROR(VLOOKUP(LOG_RESEAU[[#This Row],[Cell_ID]],Registre_Maintenance!A:D,4,FALSE),"Non trouvé") -> Non trouvé | H92: =IFERROR(VLOOKUP(LOG_RESEAU[[#This Row],[Cell_ID]],Registre_Maintenance!A:E,5,FALSE),"Non trouvé") -> Non trouvé | I92: =IFERROR(VLOOKUP(LOG_RESEAU[[#This Row],[Cell_ID]],Registre_Maintenance!A:F,6,FALSE),"Non trouvé") -> Non trouvé | J92: =IF(ISERROR(SEARCH("Non trouvé",F92)),"OK","Antenne inconnue") -> Antenne inconnue | K92: =COUNTIF(A:A,A92) -> 5 | L92: =SUMIF(A:A,A92,C:C) -> 320
A93: ANT-0019 | B93: 45213.963 | C93: 25 | D93: Non Résolu | E93: =IFERROR(VLOOKUP(LOG_RESEAU[[#This Row],[Cell_ID]],Registre_Maintenance!A:B,2,FALSE),"Non trouvé") -> Non trouvé | F93: =IFERROR(VLOOKUP(LOG_RESEAU[[#This Row],[Cell_ID]],Registre_Maintenance!A:C,3,FALSE),"Non trouvé") -> Non trouvé | G93: =IFERROR(VLOOKUP(LOG_RESEAU[[#This Row],[Cell_ID]],Registre_Maintenance!A:D,4,FALSE),"Non trouvé") -> Non trouvé | H93: =IFERROR(VLOOKUP(LOG_RESEAU[[#This Row],[Cell_ID]],Registre_Maintenance!A:E,5,FALSE),"Non trouvé") -> Non trouvé | I93: =IFERROR(VLOOKUP(LOG_RESEAU[[#This Row],[Cell_ID]],Registre_Maintenance!A:F,6,FALSE),"Non trouvé") -> Non trouvé | J93: =IF(ISERROR(SEARCH("Non trouvé",F93)),"OK","Antenne inconnue") -> Antenne inconnue | K93: =COUNTIF(A:A,A93) -> 5 | L93: =SUMIF(A:A,A93,C:C) -> 320
A94: ANT-0020 | B94: 45213.44 | C94: 15 | D94: Non Résolu | E94: =IFERROR(VLOOKUP(LOG_RESEAU[[#This Row],[Cell_ID]],Registre_Maintenance!A:B,2,FALSE),"Non trouvé") -> Kasai | F94: =IFERROR(VLOOKUP(LOG_RESEAU[[#This Row],[Cell_ID]],Registre_Maintenance!A:C,3,FALSE),"Non trouvé") -> -10.059846 | G94: =IFERROR(VLOOKUP(LOG_RESEAU[[#This Row],[Cell_ID]],Registre_Maintenance!A:D,4,FALSE),"Non trouvé") -> 14.375758 | H94: =IFERROR(VLOOKUP(LOG_RESEAU[[#This Row],[Cell_ID]],Registre_Maintenance!A:E,5,FALSE),"Non trouvé") -> 4G | I94: =IFERROR(VLOOKUP(LOG_RESEAU[[#This Row],[Cell_ID]],Registre_Maintenance!A:F,6,FALSE),"Non trouvé") -> Huawei | J94: =IF(ISERROR(SEARCH("Non trouvé",F94)),"OK","Antenne inconnue") -> OK | K94: =COUNTIF(A:A,A94) -> 6 | L94: =SUMIF(A:A,A94,C:C) -> 340
A95: ANT-0020 | B95: 45211.222 | C95: 50 | D95: Résolu | E95: =IFERROR(VLOOKUP(LOG_RESEAU[[#This Row],[Cell_ID]],Registre_Maintenance!A:B,2,FALSE),"Non trouvé") -> Kasai | F95: =IFERROR(VLOOKUP(LOG_RESEAU[[#This Row],[Cell_ID]],Registre_Maintenance!A:C,3,FALSE),"Non trouvé") -> -10.059846 | G95: =IFERROR(VLOOKUP(LOG_RESEAU[[#This Row],[Cell_ID]],Registre_Maintenance!A:D,4,FALSE),"Non trouvé") -> 14.375758 | H95: =IFERROR(VLOOKUP(LOG_RESEAU[[#This Row],[Cell_ID]],Registre_Maintenance!A:E,5,FALSE),"Non trouvé") -> 4G | I95: =IFERROR(VLOOKUP(LOG_RESEAU[[#This Row],[Cell_ID]],Registre_Maintenance!A:F,6,FALSE),"Non trouvé") -> Huawei | J95: =IF(ISERROR(SEARCH("Non trouvé",F95)),"OK","Antenne inconnue") -> OK | K95: =COUNTIF(A:A,A95) -> 6 | L95: =SUMIF(A:A,A95,C:C) -> 340
A96: ANT-0020 | B96: 45207.149 | C96: 60 | D96: Non Résolu | E96: =IFERROR(VLOOKUP(LOG_RESEAU[[#This Row],[Cell_ID]],Registre_Maintenance!A:B,2,FALSE),"Non trouvé") -> Kasai | F96: =IFERROR(VLOOKUP(LOG_RESEAU[[#This Row],[Cell_ID]],Registre_Maintenance!A:C,3,FALSE),"Non trouvé") -> -10.059846 | G96: =IFERROR(VLOOKUP(LOG_RESEAU[[#This Row],[Cell_ID]],Registre_Maintenance!A:D,4,FALSE),"Non trouvé") -> 14.375758 | H96: =IFERROR(VLOOKUP(LOG_RESEAU[[#This Row],[Cell_ID]],Registre_Maintenance!A:E,5,FALSE),"Non trouvé") -> 4G | I96: =IFERROR(VLOOKUP(LOG_RESEAU[[#This Row],[Cell_ID]],Registre_Maintenance!A:F,6,FALSE),"Non trouvé") -> Huawei | J96: =IF(ISERROR(SEARCH("Non trouvé",F96)),"OK","Antenne inconnue") -> OK | K96: =COUNTIF(A:A,A96) -> 6 | L96: =SUMIF(A:A,A96,C:C) -> 340
A97: ANT-0020 | B97: 45201.243 | C97: 40 | D97: En Cours | E97: =IFERROR(VLOOKUP(LOG_RESEAU[[#This Row],[Cell_ID]],Registre_Maintenance!A:B,2,FALSE),"Non trouvé") -> Kasai | F97: =IFERROR(VLOOKUP(LOG_RESEAU[[#This Row],[Cell_ID]],Registre_Maintenance!A:C,3,FALSE),"Non trouvé") -> -10.059846 | G97: =IFERROR(VLOOKUP(LOG_RESEAU[[#This Row],[Cell_ID]],Registre_Maintenance!A:D,4,FALSE),"Non trouvé") -> 14.375758 | H97: =IFERROR(VLOOKUP(LOG_RESEAU[[#This Row],[Cell_ID]],Registre_Maintenance!A:E,5,FALSE),"Non trouvé") -> 4G | I97: =IFERROR(VLOOKUP(LOG_RESEAU[[#This Row],[Cell_ID]],Registre_Maintenance!A:F,6,FALSE),"Non trouvé") -> Huawei | J97: =IF(ISERROR(SEARCH("Non trouvé",F97)),"OK","Antenne inconnue") -> OK | K97: =COUNTIF(A:A,A97) -> 6 | L97: =SUMIF(A:A,A97,C:C) -> 340
A98: ANT-0020 | B98: 45227.527 | C98: 78 | D98: En Cours | E98: =IFERROR(VLOOKUP(LOG_RESEAU[[#This Row],[Cell_ID]],Registre_Maintenance!A:B,2,FALSE),"Non trouvé") -> Kasai | F98: =IFERROR(VLOOKUP(LOG_RESEAU[[#This Row],[Cell_ID]],Registre_Maintenance!A:C,3,FALSE),"Non trouvé") -> -10.059846 | G98: =IFERROR(VLOOKUP(LOG_RESEAU[[#This Row],[Cell_ID]],Registre_Maintenance!A:D,4,FALSE),"Non trouvé") -> 14.375758 | H98: =IFERROR(VLOOKUP(LOG_RESEAU[[#This Row],[Cell_ID]],Registre_Maintenance!A:E,5,FALSE),"Non trouvé") -> 4G | I98: =IFERROR(VLOOKUP(LOG_RESEAU[[#This Row],[Cell_ID]],Registre_Maintenance!A:F,6,FALSE),"Non trouvé") -> Huawei | J98: =IF(ISERROR(SEARCH("Non trouvé",F98)),"OK","Antenne inconnue") -> OK | K98: =COUNTIF(A:A,A98) -> 6 | L98: =SUMIF(A:A,A98,C:C) -> 340
A99: ANT-0020 | B99: 45217.969 | C99: 97 | D99: Non Résolu | E99: =IFERROR(VLOOKUP(LOG_RESEAU[[#This Row],[Cell_ID]],Registre_Maintenance!A:B,2,FALSE),"Non trouvé") -> Kasai | F99: =IFERROR(VLOOKUP(LOG_RESEAU[[#This Row],[Cell_ID]],Registre_Maintenance!A:C,3,FALSE),"Non trouvé") -> -10.059846 | G99: =IFERROR(VLOOKUP(LOG_RESEAU[[#This Row],[Cell_ID]],Registre_Maintenance!A:D,4,FALSE),"Non trouvé") -> 14.375758 | H99: =IFERROR(VLOOKUP(LOG_RESEAU[[#This Row],[Cell_ID]],Registre_Maintenance!A:E,5,FALSE),"Non trouvé") -> 4G | I99: =IFERROR(VLOOKUP(LOG_RESEAU[[#This Row],[Cell_ID]],Registre_Maintenance!A:F,6,FALSE),"Non trouvé") -> Huawei | J99: =IF(ISERROR(SEARCH("Non trouvé",F99)),"OK","Antenne inconnue") -> OK | K99: =COUNTIF(A:A,A99) -> 6 | L99: =SUMIF(A:A,A99,C:C) -> 340
A100: ANT-0021 | B100: 45211.224 | C100: 68 | D100: Non Résolu | E100: =IFERROR(VLOOKUP(LOG_RESEAU[[#This Row],[Cell_ID]],Registre_Maintenance!A:B,2,FALSE),"Non trouvé") -> Non trouvé | F100: =IFERROR(VLOOKUP(LOG_RESEAU[[#This Row],[Cell_ID]],Registre_Maintenance!A:C,3,FALSE),"Non trouvé") -> Non trouvé | G100: =IFERROR(VLOOKUP(LOG_RESEAU[[#This Row],[Cell_ID]],Registre_Maintenance!A:D,4,FALSE),"Non trouvé") -> Non trouvé | H100: =IFERROR(VLOOKUP(LOG_RESEAU[[#This Row],[Cell_ID]],Registre_Maintenance!A:E,5,FALSE),"Non trouvé") -> Non trouvé | I100: =IFERROR(VLOOKUP(LOG_RESEAU[[#This Row],[Cell_ID]],Registre_Maintenance!A:F,6,FALSE),"Non trouvé") -> Non trouvé | J100: =IF(ISERROR(SEARCH("Non trouvé",F100)),"OK","Antenne inconnue") -> Antenne inconnue | K100: =COUNTIF(A:A,A100) -> 7 | L100: =SUMIF(A:A,A100,C:C) -> 504
B101: 45228.08 | C101: 77 | D101: Non Résolu | E101: =IFERROR(VLOOKUP(LOG_RESEAU[[#This Row],[Cell_ID]],Registre_Maintenance!A:B,2,FALSE),"Non trouvé") -> Non trouvé | F101: =IFERROR(VLOOKUP(LOG_RESEAU[[#This Row],[Cell_ID]],Registre_Maintenance!A:C,3,FALSE),"Non trouvé") -> Non trouvé | G101: =IFERROR(VLOOKUP(LOG_RESEAU[[#This Row],[Cell_ID]],Registre_Maintenance!A:D,4,FALSE),"Non trouvé") -> Non trouvé | H101: =IFERROR(VLOOKUP(LOG_RESEAU[[#This Row],[Cell_ID]],Registre_Maintenance!A:E,5,FALSE),"Non trouvé") -> Non trouvé | I101: =IFERROR(VLOOKUP(LOG_RESEAU[[#This Row],[Cell_ID]],Registre_Maintenance!A:F,6,FALSE),"Non trouvé") -> Non trouvé | J101: =IF(ISERROR(SEARCH("Non trouvé",F101)),"OK","Antenne inconnue") -> Antenne inconnue | K101: =COUNTIF(A:A,A101) -> 0 | L101: =SUMIF(A:A,A101,C:C) -> 0
A102: ANT-0021 | B102: 45230.178 | C102: 113 | D102: Résolu | E102: =IFERROR(VLOOKUP(LOG_RESEAU[[#This Row],[Cell_ID]],Registre_Maintenance!A:B,2,FALSE),"Non trouvé") -> Non trouvé | F102: =IFERROR(VLOOKUP(LOG_RESEAU[[#This Row],[Cell_ID]],Registre_Maintenance!A:C,3,FALSE),"Non trouvé") -> Non trouvé | G102: =IFERROR(VLOOKUP(LOG_RESEAU[[#This Row],[Cell_ID]],Registre_Maintenance!A:D,4,FALSE),"Non trouvé") -> Non trouvé | H102: =IFERROR(VLOOKUP(LOG_RESEAU[[#This Row],[Cell_ID]],Registre_Maintenance!A:E,5,FALSE),"Non trouvé") -> Non trouvé | I102: =IFERROR(VLOOKUP(LOG_RESEAU[[#This Row],[Cell_ID]],Registre_Maintenance!A:F,6,FALSE),"Non trouvé") -> Non trouvé | J102: =IF(ISERROR(SEARCH("Non trouvé",F102)),"OK","Antenne inconnue") -> Antenne inconnue | K102: =COUNTIF(A:A,A102) -> 7 | L102: =SUMIF(A:A,A102,C:C) -> 504
...

Sheet Registre_Maintenance
A1: ID_Antenne | B1: Province_RDC | C1: Latitude | D1: Longitude | E1: Technologie | F1: Equipementier
A2: ANT-0622 | B2: Haut-Uele | C2: -3.003879 | D2: 23.633893 | E2: 5G | F2: Ericsson
A3: ANT-0084 | B3: Kwilu | C3: 2.413557 | D3: 19.690682 | E3: 4G | F3: Huawei
A4: ANT-0862 | B4: Tanganyika | C4: -9.470862 | D4: 29.234388 | E4: 3G | F4: ZTE
A5: ANT-0288 | B5: Tshopo | C5: 1.400674 | D5: 13.503127 | E5: 5G | F5: ZTE
A6: ANT-0880 | B6: Haut-Uele | C6: 0.293756 | D6: 18.528884 | E6: 5G | F6: ZTE
A7: ANT-0847 | B7: Maniema | C7: -4.486234 | D7: 17.956159 | E7: 3G | F7: Huawei
A8: ANT-0144 | B8: Tanganyika | C8: -12.824639 | D8: 24.407249 | E8: 5G | F8: Huawei
A9: ANT-0913 | B9: Kinshasa | C9: -5.412628 | D9: 25.498236 | E9: 5G | F9: ZTE
A10: ANT-0552 | B10: Kinshasa | C10: -10.57951 | D10: 23.502314 | E10: 4G | F10: ZTE
A11: ANT-0202 | B11: Tshuapa | C11: 3.078867 | D11: 19.513651 | E11: 5G | F11: Huawei
A12: ANT-0270 | B12: Kasai-Central | C12: -1.648264 | D12: 28.866144 | E12: 5G | F12: Ericsson
A13: ANT-0752 | B13: Nord-Kivu | C13: -3.388313 | D13: 26.838507 | E13: 5G | F13: Nokia
... A243: ANT-0630 | B243: Kwango | C243: -8.121062 | D243: 21.09439 | E243: 5G | F243: ZTE
A244: ANT-0615 | C244: 3.979001 | D244: 28.069559 | E244: 3G | F244: Huawei
A245: ANT-0040 | B245: Tshopo | C245: 1.472051 | D245: 17.36289 | E245: 4G | F245: Huawei
A246: ANT-0545 | B246: Kinshasa | C246: -2.666507 | D246: 18.623693 | E246: 3G | F246: ZTE
A247: ANT-0516 | B247: Haut-Katanga | C247: -9.91705 | D247: 22.918887 | E247: 4G | F247: Huawei
A248: ANT-0121 | B248: Bas-Uele | C248: -7.395204 | D248: 21.651044 | E248: 4G | F248: Huawei
A249: ANT-0096 | B249: Tshopo | C249: 3.060376 | D249: 19.708034 | E249: 3G | F249: ZTE
A250: ANT-0796 | B250: Mai-Ndombe | C250: -3.269612 | D250: 25.571189 | E250: 5G | F250: Ericsson
A251: ANT-0789 | B251: Kasai-Central | C251: -12.086929 | D251: 14.032645 | E251: 3G | F251: ZTE
A252: ANT-0134 | B252: Kwango | C252: -10.963041 | D252: 12.269857 | E252: 4G | F252: Huawei
A253: ANT-0618 | B253: Mongala | C253: -4.332408 | D253: 14.119439 | E253: 5G | F253: Nokia
A254: ANT-0964 | B254: Kinshasa | C254: -0.571049 | D254: 15.317663 | E254: 5G | F254: Nokia
A255: ANT-0002 | B255: Mai-Ndombe | C255: -10.442425 | D255: 23.243632 | E255: 4G | F255: Nokia
A256: ANT-0695 | B256: Haut-Lomami | C256: 0.163277 | D256: 14.871577 | E256: 4G | F256: Huawei
... A470: ANT-0365 | B470: Kasai-Central | C470: -11.05534 | D470: 21.627016 | E470: 5G | F470: Nokia
A471: ANT-0160 | C471: -8.487583 | D471: 19.436312 | E471: 5G | F471: Huawei
A472: ANT-0824 | B472: Haut-Katanga | C472: -4.049072 | D472: 21.399131 | E472: 3G | F472: ZTE
A473: ANT-0123 | B473: Bas-Uele | C473: -1.689321 | D473: 30.446544 | E473: 4G | F473: Huawei
A474: ANT-0081 | B474: Tshuapa | C474: -10.577049 | D474: 23.721854 | E474: 4G | F474: ZTE
A475: ANT-0505 | B475: Sud-Kivu | C475: -11.207139 | D475: 18.702512 | E475: 5G | F475: Ericsson
A476: ANT-0863 | B476: Kasai | C476: -12.048656 | D476: 30.577876 | E476: 5G | F476: ZTE
A477: ANT-0910 | B477: Kinshasa | C477: -11.771884 | D477: 18.089173 | E477: 4G | F477: Nokia
A478: ANT-0680 | B478: Tshuapa | C478: -0.794066 | D478: 12.534793 | E478: 3G | F478: Huawei
A479: ANT-0381 | B479: Bas-Uele | C479: 4.497306 | D479: 12.857251 | E479: 5G | F479: Ericsson
A480: ANT-0323 | B480: Tshuapa | C480: -6.112606 | D480: 27.901749 | E480: 4G | F480: ZTE
A481: ANT-0952 | B481: Kwilu | C481: -0.774321 | D481: 18.628659 | E481: 4G | F481: Huawei
A482: ANT-0282 | B482: Nord-Kivu | C482: -10.25074 | D482: 26.099086 | E482: 4G | F482: Huawei
...
